Workbook

Sheet Painel
B3: CONTROLE DE GASTOS • JAPÃO 2027
B4: 30 de abril a 16 de maio de 2027 • Tóquio, Quioto e Osaka • 17 dias, 16 noites
B6: DADOS DA VIAGEM | E6: CÂMBIO — quanto vale 1 unidade em R$
B7: Data de ida | C7: 46507 | E7: Moeda | F7: Cotação (R$) | G7: Fonte da cotação
B8: Data de volta | C8: 46523 | E8: JPY | F8: 0.0325 | G8: Iene japonês - Wise, faixa 0,0322-0,0326 na semana de 04-14/08/2026
B9: Nº de viajantes | C9: 2 | E9: BRL | F9: 1 | G9: Real brasileiro - moeda base da planilha
B10: Parcelas vencem todo dia | C10: 3 | E10: USD | F10: 5.19 | G10: Dólar americano - fechamento de 13/08/2026 (R$ 5,1896)
B11: Duração (dias) | C11: =IFERROR($C$8-$C$7+1,"") -> 17 | E11: Cotações apuradas em 15/08/2026. Como a viagem é em 2027, trate como referência e atualize antes de comprar e durante a viagem.
B12: Orçamento total (R$) | C12: =SUM($C$25:$C$37) -> 0
B14: RESUMO
B16: TOTAL GASTO | D16: JÁ PAGO (parcelas incluídas) | F16: AINDA A PAGAR | H16: SALDO DO ORÇAMENTO
B17: =SUMIFS(Gastos!$J$7:$J$180,Gastos!$G$7:$G$180,"<>Reembolsado") -> 16437.86 | D17: =SUM(Gastos!$N$7:$N$180) -> 0 | F17: =SUM(Gastos!$O$7:$O$180) -> 16437.86 | H17: =IF($C$12=0,"",$C$12-$B$17)
B19: GASTO POR PESSOA | D19: GASTO POR DIA DE VIAGEM | F19: FALTA PAGAR EM PARCELAS | H19: PRÓXIMA PARCELA VENCE EM
B20: =IFERROR($B$17/$C$9,0) -> 8218.93 | D20: =IFERROR($B$17/$C$11,0) -> 966.93294 | F20: =SUMIFS(Gastos!$O$7:$O$180,Gastos!$G$7:$G$180,"Parcelado") -> 16437.86 | H20: =IF(SUMIFS(Gastos!$O$7:$O$180,Gastos!$G$7:$G$180,"Parcelado")=0,"",DATE(YEAR(TODAY()),MONTH(TODAY())+IF(DAY(TODAY())>=$C$10,1,0),$C$10)) -> 46268
B23: GASTOS POR CATEGORIA — preencha a coluna Orçamento com os seus valores
B24: Categoria | C24: Orçamento (R$) | D24: Gasto (R$) | E24: Já pago | F24: Em aberto | G24: % do total | H24: Saldo do orçamento | I24: Lançamentos
B25: =IF(Listas!$B$7="","",Listas!$B$7) -> Passagens Aéreas | D25: =SUMIFS(Gastos!$J$7:$J$180,Gastos!$B$7:$B$180,$B25,Gastos!$G$7:$G$180,"<>Reembolsado") -> 16437.86 | E25: =SUMIFS(Gastos!$N$7:$N$180,Gastos!$B$7:$B$180,$B25) -> 0 | F25: =SUMIFS(Gastos!$O$7:$O$180,Gastos!$B$7:$B$180,$B25) -> 16437.86 | G25: =IFERROR($D25/$D$38,0) -> 1 | H25: =IF($C25="","",$C25-$D25) | I25: =COUNTIFS(Gastos!$B$7:$B$180,$B25) -> 1
B26: =IF(Listas!$B$8="","",Listas!$B$8) -> Hospedagem | D26: =SUMIFS(Gastos!$J$7:$J$180,Gastos!$B$7:$B$180,$B26,Gastos!$G$7:$G$180,"<>Reembolsado") -> 0 | E26: =SUMIFS(Gastos!$N$7:$N$180,Gastos!$B$7:$B$180,$B26) -> 0 | F26: =SUMIFS(Gastos!$O$7:$O$180,Gastos!$B$7:$B$180,$B26) -> 0 | G26: =IFERROR($D26/$D$38,0) -> 0 | H26: =IF($C26="","",$C26-$D26) | I26: =COUNTIFS(Gastos!$B$7:$B$180,$B26) -> 0
B27: =IF(Listas!$B$9="","",Listas!$B$9) -> Transporte no Japão (trens/shinkansen) | D27: =SUMIFS(Gastos!$J$7:$J$180,Gastos!$B$7:$B$180,$B27,Gastos!$G$7:$G$180,"<>Reembolsado") -> 0 | E27: =SUMIFS(Gastos!$N$7:$N$180,Gastos!$B$7:$B$180,$B27) -> 0 | F27: =SUMIFS(Gastos!$O$7:$O$180,Gastos!$B$7:$B$180,$B27) -> 0 | G27: =IFERROR($D27/$D$38,0) -> 0 | H27: =IF($C27="","",$C27-$D27) | I27: =COUNTIFS(Gastos!$B$7:$B$180,$B27) -> 0
B28: =IF(Listas!$B$10="","",Listas!$B$10) -> Transporte local (metrô/ônibus/táxi) | D28: =SUMIFS(Gastos!$J$7:$J$180,Gastos!$B$7:$B$180,$B28,Gastos!$G$7:$G$180,"<>Reembolsado") -> 0 | E28: =SUMIFS(Gastos!$N$7:$N$180,Gastos!$B$7:$B$180,$B28) -> 0 | F28: =SUMIFS(Gastos!$O$7:$O$180,Gastos!$B$7:$B$180,$B28) -> 0 | G28: =IFERROR($D28/$D$38,0) -> 0 | H28: =IF($C28="","",$C28-$D28) | I28: =COUNTIFS(Gastos!$B$7:$B$180,$B28) -> 0
B29: =IF(Listas!$B$11="","",Listas!$B$11) -> Alimentação | D29: =SUMIFS(Gastos!$J$7:$J$180,Gastos!$B$7:$B$180,$B29,Gastos!$G$7:$G$180,"<>Reembolsado") -> 0 | E29: =SUMIFS(Gastos!$N$7:$N$180,Gastos!$B$7:$B$180,$B29) -> 0 | F29: =SUMIFS(Gastos!$O$7:$O$180,Gastos!$B$7:$B$180,$B29) -> 0 | G29: =IFERROR($D29/$D$38,0) -> 0 | H29: =IF($C29="","",$C29-$D29) | I29: =COUNTIFS(Gastos!$B$7:$B$180,$B29) -> 0
B30: =IF(Listas!$B$12="","",Listas!$B$12) -> Passeios e Ingressos | D30: =SUMIFS(Gastos!$J$7:$J$180,Gastos!$B$7:$B$180,$B30,Gastos!$G$7:$G$180,"<>Reembolsado") -> 0 | E30: =SUMIFS(Gastos!$N$7:$N$180,Gastos!$B$7:$B$180,$B30) -> 0 | F30: =SUMIFS(Gastos!$O$7:$O$180,Gastos!$B$7:$B$180,$B30) -> 0 | G30: =IFERROR($D30/$D$38,0) -> 0 | H30: =IF($C30="","",$C30-$D30) | I30: =COUNTIFS(Gastos!$B$7:$B$180,$B30) -> 0
B31: =IF(Listas!$B$13="","",Listas!$B$13) -> Tokyo Disney | D31: =SUMIFS(Gastos!$J$7:$J$180,Gastos!$B$7:$B$180,$B31,Gastos!$G$7:$G$180,"<>Reembolsado") -> 0 | E31: =SUMIFS(Gastos!$N$7:$N$180,Gastos!$B$7:$B$180,$B31) -> 0 | F31: =SUMIFS(Gastos!$O$7:$O$180,Gastos!$B$7:$B$180,$B31) -> 0 | G31: =IFERROR($D31/$D$38,0) -> 0 | H31: =IF($C31="","",$C31-$D31) | I31: =COUNTIFS(Gastos!$B$7:$B$180,$B31) -> 0
B32: =IF(Listas!$B$14="","",Listas!$B$14) -> Compras e Souvenirs | D32: =SUMIFS(Gastos!$J$7:$J$180,Gastos!$B$7:$B$180,$B32,Gastos!$G$7:$G$180,"<>Reembolsado") -> 0 | E32: =SUMIFS(Gastos!$N$7:$N$180,Gastos!$B$7:$B$180,$B32) -> 0 | F32: =SUMIFS(Gastos!$O$7:$O$180,Gastos!$B$7:$B$180,$B32) -> 0 | G32: =IFERROR($D32/$D$38,0) -> 0 | H32: =IF($C32="","",$C32-$D32) | I32: =COUNTIFS(Gastos!$B$7:$B$180,$B32) -> 0
B33: =IF(Listas!$B$15="","",Listas!$B$15) -> Seguro Viagem | D33: =SUMIFS(Gastos!$J$7:$J$180,Gastos!$B$7:$B$180,$B33,Gastos!$G$7:$G$180,"<>Reembolsado") -> 0 | E33: =SUMIFS(Gastos!$N$7:$N$180,Gastos!$B$7:$B$180,$B33) -> 0 | F33: =SUMIFS(Gastos!$O$7:$O$180,Gastos!$B$7:$B$180,$B33) -> 0 | G33: =IFERROR($D33/$D$38,0) -> 0 | H33: =IF($C33="","",$C33-$D33) | I33: =COUNTIFS(Gastos!$B$7:$B$180,$B33) -> 0
B34: =IF(Listas!$B$16="","",Listas!$B$16) -> Chip / Internet | D34: =SUMIFS(Gastos!$J$7:$J$180,Gastos!$B$7:$B$180,$B34,Gastos!$G$7:$G$180,"<>Reembolsado") -> 0 | E34: =SUMIFS(Gastos!$N$7:$N$180,Gastos!$B$7:$B$180,$B34) -> 0 | F34: =SUMIFS(Gastos!$O$7:$O$180,Gastos!$B$7:$B$180,$B34) -> 0 | G34: =IFERROR($D34/$D$38,0) -> 0 | H34: =IF($C34="","",$C34-$D34) | I34: =COUNTIFS(Gastos!$B$7:$B$180,$B34) -> 0
B35: =IF(Listas!$B$17="","",Listas!$B$17) -> Documentos (passaporte etc.) | D35: =SUMIFS(Gastos!$J$7:$J$180,Gastos!$B$7:$B$180,$B35,Gastos!$G$7:$G$180,"<>Reembolsado") -> 0 | E35: =SUMIFS(Gastos!$N$7:$N$180,Gastos!$B$7:$B$180,$B35) -> 0 | F35: =SUMIFS(Gastos!$O$7:$O$180,Gastos!$B$7:$B$180,$B35) -> 0 | G35: =IFERROR($D35/$D$38,0) -> 0 | H35: =IF($C35="","",$C35-$D35) | I35: =COUNTIFS(Gastos!$B$7:$B$180,$B35) -> 0
B36: =IF(Listas!$B$18="","",Listas!$B$18) -> Bagagem e Equipamentos | D36: =SUMIFS(Gastos!$J$7:$J$180,Gastos!$B$7:$B$180,$B36,Gastos!$G$7:$G$180,"<>Reembolsado") -> 0 | E36: =SUMIFS(Gastos!$N$7:$N$180,Gastos!$B$7:$B$180,$B36) -> 0 | F36: =SUMIFS(Gastos!$O$7:$O$180,Gastos!$B$7:$B$180,$B36) -> 0 | G36: =IFERROR($D36/$D$38,0) -> 0 | H36: =IF($C36="","",$C36-$D36) | I36: =COUNTIFS(Gastos!$B$7:$B$180,$B36) -> 0
B37: =IF(Listas!$B$19="","",Listas!$B$19) -> Outros | D37: =SUMIFS(Gastos!$J$7:$J$180,Gastos!$B$7:$B$180,$B37,Gastos!$G$7:$G$180,"<>Reembolsado") -> 0 | E37: =SUMIFS(Gastos!$N$7:$N$180,Gastos!$B$7:$B$180,$B37) -> 0 | F37: =SUMIFS(Gastos!$O$7:$O$180,Gastos!$B$7:$B$180,$B37) -> 0 | G37: =IFERROR($D37/$D$38,0) -> 0 | H37: =IF($C37="","",$C37-$D37) | I37: =COUNTIFS(Gastos!$B$7:$B$180,$B37) -> 0
B38: TOTAL | C38: =SUM(C25:C37) -> 0 | D38: =SUM(D25:D37) -> 16437.86 | E38: =SUM(E25:E37) -> 0 | F38: =SUM(F25:F37) -> 16437.86 | G38: =SUM(G25:G37) -> 1 | H38: =SUM(H25:H37) -> 0 | I38: =SUM(I25:I37) -> 1
B40: POR FORMA DE PAGAMENTO | G40: POR PESSOA
B41: Forma de pagamento | C41: Total (R$) | D41: Já pago | E41: Em aberto | G41: Quem pagou | H41: Total (R$) | I41: Em aberto
B42: =IF(Listas!$D$7="","",Listas!$D$7) -> Dinheiro (iene) | C42: =SUMIFS(Gastos!$J$7:$J$180,Gastos!$F$7:$F$180,$B42) -> 0 | D42: =SUMIFS(Gastos!$N$7:$N$180,Gastos!$F$7:$F$180,$B42) -> 0 | E42: =SUMIFS(Gastos!$O$7:$O$180,Gastos!$F$7:$F$180,$B42) -> 0 | G42: =IF(Listas!$H$7="","",Listas!$H$7) -> Viajante 1 | H42: =SUMIFS(Gastos!$J$7:$J$180,Gastos!$E$7:$E$180,$G42) -> 0 | I42: =SUMIFS(Gastos!$O$7:$O$180,Gastos!$E$7:$E$180,$G42) -> 0
B43: =IF(Listas!$D$8="","",Listas!$D$8) -> Dinheiro (real) | C43: =SUMIFS(Gastos!$J$7:$J$180,Gastos!$F$7:$F$180,$B43) -> 0 | D43: =SUMIFS(Gastos!$N$7:$N$180,Gastos!$F$7:$F$180,$B43) -> 0 | E43: =SUMIFS(Gastos!$O$7:$O$180,Gastos!$F$7:$F$180,$B43) -> 0 | G43: =IF(Listas!$H$8="","",Listas!$H$8) -> Viajante 2 | H43: =SUMIFS(Gastos!$J$7:$J$180,Gastos!$E$7:$E$180,$G43) -> 0 | I43: =SUMIFS(Gastos!$O$7:$O$180,Gastos!$E$7:$E$180,$G43) -> 0
B44: =IF(Listas!$D$9="","",Listas!$D$9) -> Cartão de crédito | C44: =SUMIFS(Gastos!$J$7:$J$180,Gastos!$F$7:$F$180,$B44) -> 0 | D44: =SUMIFS(Gastos!$N$7:$N$180,Gastos!$F$7:$F$180,$B44) -> 0 | E44: =SUMIFS(Gastos!$O$7:$O$180,Gastos!$F$7:$F$180,$B44) -> 0 | G44: =IF(Listas!$H$9="","",Listas!$H$9) -> Dividido | H44: =SUMIFS(Gastos!$J$7:$J$180,Gastos!$E$7:$E$180,$G44) -> 16437.86 | I44: =SUMIFS(Gastos!$O$7:$O$180,Gastos!$E$7:$E$180,$G44) -> 16437.86
B45: =IF(Listas!$D$10="","",Listas!$D$10) -> Cartão de débito | C45: =SUMIFS(Gastos!$J$7:$J$180,Gastos!$F$7:$F$180,$B45) -> 0 | D45: =SUMIFS(Gastos!$N$7:$N$180,Gastos!$F$7:$F$180,$B45) -> 0 | E45: =SUMIFS(Gastos!$O$7:$O$180,Gastos!$F$7:$F$180,$B45) -> 0
B46: =IF(Listas!$D$11="","",Listas!$D$11) -> Cartão internacional (Wise/Nomad) | C46: =SUMIFS(Gastos!$J$7:$J$180,Gastos!$F$7:$F$180,$B46) -> 0 | D46: =SUMIFS(Gastos!$N$7:$N$180,Gastos!$F$7:$F$180,$B46) -> 0 | E46: =SUMIFS(Gastos!$O$7:$O$180,Gastos!$F$7:$F$180,$B46) -> 0
B47: =IF(Listas!$D$12="","",Listas!$D$12) -> IC Card (Suica/Pasmo) | C47: =SUMIFS(Gastos!$J$7:$J$180,Gastos!$F$7:$F$180,$B47) -> 0 | D47: =SUMIFS(Gastos!$N$7:$N$180,Gastos!$F$7:$F$180,$B47) -> 0 | E47: =SUMIFS(Gastos!$O$7:$O$180,Gastos!$F$7:$F$180,$B47) -> 0
B48: =IF(Listas!$D$13="","",Listas!$D$13) -> PIX | C48: =SUMIFS(Gastos!$J$7:$J$180,Gastos!$F$7:$F$180,$B48) -> 0 | D48: =SUMIFS(Gastos!$N$7:$N$180,Gastos!$F$7:$F$180,$B48) -> 0 | E48: =SUMIFS(Gastos!$O$7:$O$180,Gastos!$F$7:$F$180,$B48) -> 0
B49: =IF(Listas!$D$14="","",Listas!$D$14) -> Transferência / Boleto | C49: =SUMIFS(Gastos!$J$7:$J$180,Gastos!$F$7:$F$180,$B49) -> 0 | D49: =SUMIFS(Gastos!$N$7:$N$180,Gastos!$F$7:$F$180,$B49) -> 0 | E49: =SUMIFS(Gastos!$O$7:$O$180,Gastos!$F$7:$F$180,$B49) -> 0
...

Sheet Gastos
A3: LANÇAMENTO DE GASTOS • JAPÃO 2027
A4: Uma linha por gasto. As colunas cinza são calculadas sozinhas — inclusive as parcelas, que avançam automaticamente a cada vencimento.
A6: Data | B6: Categoria | C6: Descrição | D6: Cidade / Local | E6: Quem pagou | F6: Forma de pagamento | G6: Status | H6: Moeda | I6: Valor pago | J6: Valor total (R$) | K6: Nº de parcelas | L6: 1ª parcela em | M6: Parcelas pagas | N6: Já pago (R$) | O6: Ainda a pagar (R$) | P6: Observações
B7: Passagens Aéreas | C7: Passagens aéreas Brasil - Tóquio (ida e volta, 2 pessoas) | D7: Brasil (pré-viagem) | E7: Dividido | G7: Parcelado | H7: BRL | I7: 16437.86 | J7: =IF($I7="","",IFERROR($I7*INDEX(TAXAS,MATCH($H7,MOEDAS,0)),"")) -> 16437.86 | K7: 9 | L7: 46268 | M7: =IF($G7<>"Parcelado",0,IF(OR($K7="",$L7=""),0,MIN($K7,MAX(0,(YEAR(TODAY())-YEAR($L7))*12+(MONTH(TODAY())-MONTH($L7))+IF(DAY(TODAY())>=DAY($L7),1,0))))) -> 0 | N7: =IF($J7="","",IF($G7="Pago",$J7,IF($G7="Reembolsado",0,IF($G7="Parcelado",IFERROR($J7/$K7*$M7,0),0)))) -> 0 | O7: =IF($J7="","",IF($G7="Reembolsado",0,$J7-$N7)) -> 16437.86 | P7: Parcelado em 9x, todo dia 3. Preencha a data da compra e a forma de pagamento.
J8: =IF($I8="","",IFERROR($I8*INDEX(TAXAS,MATCH($H8,MOEDAS,0)),"")) | M8: =IF($G8<>"Parcelado",0,IF(OR($K8="",$L8=""),0,MIN($K8,MAX(0,(YEAR(TODAY())-YEAR($L8))*12+(MONTH(TODAY())-MONTH($L8))+IF(DAY(TODAY())>=DAY($L8),1,0))))) -> 0 | N8: =IF($J8="","",IF($G8="Pago",$J8,IF($G8="Reembolsado",0,IF($G8="Parcelado",IFERROR($J8/$K8*$M8,0),0)))) | O8: =IF($J8="","",IF($G8="Reembolsado",0,$J8-$N8))
J9: =IF($I9="","",IFERROR($I9*INDEX(TAXAS,MATCH($H9,MOEDAS,0)),"")) | M9: =IF($G9<>"Parcelado",0,IF(OR($K9="",$L9=""),0,MIN($K9,MAX(0,(YEAR(TODAY())-YEAR($L9))*12+(MONTH(TODAY())-MONTH($L9))+IF(DAY(TODAY())>=DAY($L9),1,0))))) -> 0 | N9: =IF($J9="","",IF($G9="Pago",$J9,IF($G9="Reembolsado",0,IF($G9="Parcelado",IFERROR($J9/$K9*$M9,0),0)))) | O9: =IF($J9="","",IF($G9="Reembolsado",0,$J9-$N9))
J10: =IF($I10="","",IFERROR($I10*INDEX(TAXAS,MATCH($H10,MOEDAS,0)),"")) | M10: =IF($G10<>"Parcelado",0,IF(OR($K10="",$L10=""),0,MIN($K10,MAX(0,(YEAR(TODAY())-YEAR($L10))*12+(MONTH(TODAY())-MONTH($L10))+IF(DAY(TODAY())>=DAY($L10),1,0))))) -> 0 | N10: =IF($J10="","",IF($G10="Pago",$J10,IF($G10="Reembolsado",0,IF($G10="Parcelado",IFERROR($J10/$K10*$M10,0),0)))) | O10: =IF($J10="","",IF($G10="Reembolsado",0,$J10-$N10))
J11: =IF($I11="","",IFERROR($I11*INDEX(TAXAS,MATCH($H11,MOEDAS,0)),"")) | M11: =IF($G11<>"Parcelado",0,IF(OR($K11="",$L11=""),0,MIN($K11,MAX(0,(YEAR(TODAY())-YEAR($L11))*12+(MONTH(TODAY())-MONTH($L11))+IF(DAY(TODAY())>=DAY($L11),1,0))))) -> 0 | N11: =IF($J11="","",IF($G11="Pago",$J11,IF($G11="Reembolsado",0,IF($G11="Parcelado",IFERROR($J11/$K11*$M11,0),0)))) | O11: =IF($J11="","",IF($G11="Reembolsado",0,$J11-$N11))
J12: =IF($I12="","",IFERROR($I12*INDEX(TAXAS,MATCH($H12,MOEDAS,0)),"")) | M12: =IF($G12<>"Parcelado",0,IF(OR($K12="",$L12=""),0,MIN($K12,MAX(0,(YEAR(TODAY())-YEAR($L12))*12+(MONTH(TODAY())-MONTH($L12))+IF(DAY(TODAY())>=DAY($L12),1,0))))) -> 0 | N12: =IF($J12="","",IF($G12="Pago",$J12,IF($G12="Reembolsado",0,IF($G12="Parcelado",IFERROR($J12/$K12*$M12,0),0)))) | O12: =IF($J12="","",IF($G12="Reembolsado",0,$J12-$N12))
J13: =IF($I13="","",IFERROR($I13*INDEX(TAXAS,MATCH($H13,MOEDAS,0)),"")) | M13: =IF($G13<>"Parcelado",0,IF(OR($K13="",$L13=""),0,MIN($K13,MAX(0,(YEAR(TODAY())-YEAR($L13))*12+(MONTH(TODAY())-MONTH($L13))+IF(DAY(TODAY())>=DAY($L13),1,0))))) -> 0 | N13: =IF($J13="","",IF($G13="Pago",$J13,IF($G13="Reembolsado",0,IF($G13="Parcelado",IFERROR($J13/$K13*$M13,0),0)))) | O13: =IF($J13="","",IF($G13="Reembolsado",0,$J13-$N13))
J14: =IF($I14="","",IFERROR($I14*INDEX(TAXAS,MATCH($H14,MOEDAS,0)),"")) | M14: =IF($G14<>"Parcelado",0,IF(OR($K14="",$L14=""),0,MIN($K14,MAX(0,(YEAR(TODAY())-YEAR($L14))*12+(MONTH(TODAY())-MONTH($L14))+IF(DAY(TODAY())>=DAY($L14),1,0))))) -> 0 | N14: =IF($J14="","",IF($G14="Pago",$J14,IF($G14="Reembolsado",0,IF($G14="Parcelado",IFERROR($J14/$K14*$M14,0),0)))) | O14: =IF($J14="","",IF($G14="Reembolsado",0,$J14-$N14))
J15: =IF($I15="","",IFERROR($I15*INDEX(TAXAS,MATCH($H15,MOEDAS,0)),"")) | M15: =IF($G15<>"Parcelado",0,IF(OR($K15="",$L15=""),0,MIN($K15,MAX(0,(YEAR(TODAY())-YEAR($L15))*12+(MONTH(TODAY())-MONTH($L15))+IF(DAY(TODAY())>=DAY($L15),1,0))))) -> 0 | N15: =IF($J15="","",IF($G15="Pago",$J15,IF($G15="Reembolsado",0,IF($G15="Parcelado",IFERROR($J15/$K15*$M15,0),0)))) | O15: =IF($J15="","",IF($G15="Reembolsado",0,$J15-$N15))
J16: =IF($I16="","",IFERROR($I16*INDEX(TAXAS,MATCH($H16,MOEDAS,0)),"")) | M16: =IF($G16<>"Parcelado",0,IF(OR($K16="",$L16=""),0,MIN($K16,MAX(0,(YEAR(TODAY())-YEAR($L16))*12+(MONTH(TODAY())-MONTH($L16))+IF(DAY(TODAY())>=DAY($L16),1,0))))) -> 0 | N16: =IF($J16="","",IF($G16="Pago",$J16,IF($G16="Reembolsado",0,IF($G16="Parcelado",IFERROR($J16/$K16*$M16,0),0)))) | O16: =IF($J16="","",IF($G16="Reembolsado",0,$J16-$N16))
J17: =IF($I17="","",IFERROR($I17*INDEX(TAXAS,MATCH($H17,MOEDAS,0)),"")) | M17: =IF($G17<>"Parcelado",0,IF(OR($K17="",$L17=""),0,MIN($K17,MAX(0,(YEAR(TODAY())-YEAR($L17))*12+(MONTH(TODAY())-MONTH($L17))+IF(DAY(TODAY())>=DAY($L17),1,0))))) -> 0 | N17: =IF($J17="","",IF($G17="Pago",$J17,IF($G17="Reembolsado",0,IF($G17="Parcelado",IFERROR($J17/$K17*$M17,0),0)))) | O17: =IF($J17="","",IF($G17="Reembolsado",0,$J17-$N17))
J18: =IF($I18="","",IFERROR($I18*INDEX(TAXAS,MATCH($H18,MOEDAS,0)),"")) | M18: =IF($G18<>"Parcelado",0,IF(OR($K18="",$L18=""),0,MIN($K18,MAX(0,(YEAR(TODAY())-YEAR($L18))*12+(MONTH(TODAY())-MONTH($L18))+IF(DAY(TODAY())>=DAY($L18),1,0))))) -> 0 | N18: =IF($J18="","",IF($G18="Pago",$J18,IF($G18="Reembolsado",0,IF($G18="Parcelado",IFERROR($J18/$K18*$M18,0),0)))) | O18: =IF($J18="","",IF($G18="Reembolsado",0,$J18-$N18))
J19: =IF($I19="","",IFERROR($I19*INDEX(TAXAS,MATCH($H19,MOEDAS,0)),"")) | M19: =IF($G19<>"Parcelado",0,IF(OR($K19="",$L19=""),0,MIN($K19,MAX(0,(YEAR(TODAY())-YEAR($L19))*12+(MONTH(TODAY())-MONTH($L19))+IF(DAY(TODAY())>=DAY($L19),1,0))))) -> 0 | N19: =IF($J19="","",IF($G19="Pago",$J19,IF($G19="Reembolsado",0,IF($G19="Parcelado",IFERROR($J19/$K19*$M19,0),0)))) | O19: =IF($J19="","",IF($G19="Reembolsado",0,$J19-$N19))
... J180: =IF($I180="","",IFERROR($I180*INDEX(TAXAS,MATCH($H180,MOEDAS,0)),"")) | M180: =IF($G180<>"Parcelado",0,IF(OR($K180="",$L180=""),0,MIN($K180,MAX(0,(YEAR(TODAY())-YEAR($L180))*12+(MONTH(TODAY())-MONTH($L180))+IF(DAY(TODAY())>=DAY($L180),1,0))))) -> 0 | N180: =IF($J180="","",IF($G180="Pago",$J180,IF($G180="Reembolsado",0,IF($G180="Parcelado",IFERROR($J180/$K180*$M180,0),0)))) | O180: =IF($J180="","",IF($G180="Reembolsado",0,$J180-$N180))

Sheet Roteiro
B3: ROTEIRO E DICAS • JAPÃO 2027
B4: Sugestão de 17 dias entrando e saindo por Tóquio, com Quioto, Osaka, Monte Fuji e Tokyo Disney
B6: ATENÇÃO — SUA VIAGEM COMEÇA DENTRO DA GOLDEN WEEK
B7: A Golden Week de 2027 vai de quinta 29/04 a quarta 05/05 — quatro feriados nacionais emendados. É o feriadão em que o Japão inteiro viaja ao mesmo tempo.
B8: Pico de saída das cidades: 29 e 30/04 (vocês pousam justamente no dia 30). Pico de volta: 04 e 05/05. Nesses dias, evite deslocamento entre cidades.
B9: Por isso o roteiro abaixo mantém vocês parados em Tóquio até 07/05 e só então desce para Quioto: shinkansen lotado e hotel caro nessas datas, e a cidade fica mais tranquila porque muito japonês viaja para fora.
B10: Consequência prática: a hospedagem em Tóquio de 30/04 a 07/05 é a reserva mais urgente de todas. Hotel bom em Golden Week esgota com meses de antecedência.
B12: RESUMO DO ROTEIRO
B13: Trecho | F13: Datas | I13: Noites | J13: Por quê
B14: Tóquio | F14: 30/04 a 07/05 | I14: 7 | J14: Atravessar a Golden Week sem trocar de cidade
B15: Monte Fuji (bate-volta) | F15: 06/05 | I15: — | J15: Feriadão acabou: estrada e ônibus liberam
B16: Tokyo Disney | F16: 07/05 | I16: — | J16: Sexta pós-feriado: dia mais calmo do período
B17: Quioto | F17: 08/05 a 12/05 | I17: 4 | J17: Templos, Arashiyama e bate-volta a Nara
B18: Osaka | F18: 12/05 a 15/05 | I18: 3 | J18: Comida, Dotonbori e Universal Studios (opcional)
B19: Tóquio (última noite) | F19: 15/05 a 16/05 | I19: 1 | J19: Volta de shinkansen e voo no dia 16
B21: ROTEIRO DIA A DIA — sugestão, ajuste como quiser
B22: Data | C22: Dia | D22: Base | F22: Programa sugerido | J22: Observação
B23: 30/04 | C23: sex | D23: Tóquio | F23: Chegada. Comprar o IC card (Welcome Suica / Tourist Pasmo) no aeroporto, check-in e um jantar leve perto do hotel. | J23: Pico da Golden Week. Não marque nada exigente no dia da chegada.
B24: 01/05 | C24: sáb | D24: Tóquio | F24: Shibuya (cruzamento e Shibuya Sky), Harajuku e Takeshita, Meiji Jingu, Omotesando. | J24: Shibuya Sky é ingresso datado — compre online semanas antes.
B25: 02/05 | C25: dom | D25: Tóquio | F25: Asakusa e o templo Senso-ji, rua Nakamise, Tokyo Skytree, parque e museus de Ueno. | J25: Chegue em Senso-ji antes das 9h para escapar do fluxo.
B26: 03/05 | C26: seg | D26: Tóquio | F26: Shinjuku: jardim Gyoen, Omoide Yokocho, Kabukicho e o mirante grátis do Tocho. | J26: Feriado da Constituição. Prefira bairro a cartão-postal.
B27: 04/05 | C27: ter | D27: Tóquio | F27: teamLab, Odaiba, ou Ginza com o mercado externo de Tsukiji pela manhã. | J27: Feriado. teamLab é ingresso datado, esgota.
B28: 05/05 | C28: qua | D28: Tóquio | F28: Bairros com menos turista: Shimokitazawa, Nakameguro, Yanaka, Koenji. Akihabara à noite. | J28: Último feriado do bloco e pico de volta às cidades.
B29: 06/05 | C29: qui | D29: Monte Fuji | F29: Bate-volta a Kawaguchiko: pagode Chureito, Oishi Park, lago Kawaguchi. Se o festival estiver aberto, Fuji Shibazakura. | J29: Ônibus do terminal Busta Shinjuku, ~2h, reserve antes. Festival costuma ir de meados de abril a fim de maio — confirme as datas de 2027.
B30: 07/05 | C30: sex | D30: Tokyo Disney | F30: Um dia inteiro: DisneySea (único no mundo, área Fantasy Springs) ou Disneyland (o clássico). | J30: Ingresso entra à venda exatamente 2 meses antes, 14h no Japão = 02h de Brasília do dia 07/03/2027. Datas boas esgotam em horas.
B31: 08/05 | C31: sáb | D31: Tóquio → Quioto | F31: Shinkansen de manhã (~2h15). À tarde, Higashiyama: Kiyomizu-dera e Gion no fim do dia. | J31: Reserve assento pelo smartEX. Considere mandar a mala por takkyubin.
B32: 09/05 | C32: dom | D32: Quioto | F32: Arashiyama: bambuzal, templo Tenryu-ji e o parque dos macacos. À tarde, Kinkaku-ji (Pavilhão Dourado). | J32: Bambuzal antes das 8h ou depois das 17h — no meio do dia é impraticável.
B33: 10/05 | C33: seg | D33: Quioto | F33: Fushimi Inari (os mil torii), templo Tofuku-ji e mercado Nishiki. | J33: Fushimi Inari é aberto 24h e de graça: vá bem cedo ou no fim da tarde.
... B39: 16/05 | C39: dom | D39: Voo de volta | F39: Traslado ao aeroporto: Narita ~1h a 1h30, Haneda ~40 min. | J39: Chegue 3h antes. Dá para devolver o IC card e resgatar o saldo.
B41: O QUE VER EM CADA LUGAR
B42: Lugar | E42: Destaques
B43: Tóquio | E43: Shibuya e o cruzamento • Shibuya Sky • Shinjuku e o Gyoen • Asakusa e Senso-ji • Tokyo Skytree • Ueno • Akihabara • Ginza e Tsukiji • Meiji Jingu e Harajuku • teamLab • Yanaka e Shimokitazawa para fugir da multidão
B44: Monte Fuji / Kawaguchiko | E44: Pagode Chureito (a foto clássica) • Oishi Park à beira do lago Kawaguchi • teleférico Kachi Kachi • Fuji Shibazakura, o tapete de flores rosa, que costuma abrir de meados de abril a fim de maio
B45: Tokyo Disney | E45: DisneySea: não existe igual no mundo, e a área Fantasy Springs é a mais nova • Disneyland: o parque clássico, melhor com crianças • Premier Access no app para furar fila em atração específica
B46: Quioto | E46: Kiyomizu-dera • Fushimi Inari • Arashiyama e o bambuzal • Kinkaku-ji • Ginkaku-ji e o Caminho do Filósofo • Gion ao entardecer • mercado Nishiki • Ryoan-ji e seu jardim zen
B47: Nara (bate-volta) | E47: Todai-ji e o Grande Buda de bronze • parque dos cervos soltos • Kasuga Taisha e suas lanternas
B48: Osaka | E48: Dotonbori e o letreiro do Glico • Namba • Castelo de Osaka • Umeda Sky Building • Shinsekai e Tsutenkaku • mercado Kuromon • Universal Studios Japan
B50: O QUE RESERVAR E QUANDO — em ordem de urgência
B51: O que reservar | F51: Quando | J51: Status
B52: Hospedagem em Tóquio (30/04 a 07/05) | F52: Assim que possível — é Golden Week, esgota com meses de antecedência | J52: A fazer
...

Sheet Por Dia
A3: GASTOS DIA A DIA
A4: As datas saem da ida e da volta informadas no Painel. Tudo aqui é calculado automaticamente.
A6: Data | B6: Total do dia (R$) | C6: Acumulado (R$) | D6: =Listas!$B$11 -> Alimentação | E6: =Listas!$B$10 -> Transporte local (metrô/ônibus/táxi) | F6: =Listas!$B$12 -> Passeios e Ingressos | G6: =Listas!$B$14 -> Compras e Souvenirs | H6: Demais categorias | I6: Lançamentos
A7: =IF(Painel!$C$7="","",Painel!$C$7) -> 46507 | B7: =IF($A7="","",SUMIFS(Gastos!$J$7:$J$180,Gastos!$A$7:$A$180,$A7)) -> 0 | C7: =IF($A7="","",SUM($B$7:$B7)) -> 0 | D7: =IF($A7="","",SUMIFS(Gastos!$J$7:$J$180,Gastos!$A$7:$A$180,$A7,Gastos!$B$7:$B$180,D$6)) -> 0 | E7: =IF($A7="","",SUMIFS(Gastos!$J$7:$J$180,Gastos!$A$7:$A$180,$A7,Gastos!$B$7:$B$180,E$6)) -> 0 | F7: =IF($A7="","",SUMIFS(Gastos!$J$7:$J$180,Gastos!$A$7:$A$180,$A7,Gastos!$B$7:$B$180,F$6)) -> 0 | G7: =IF($A7="","",SUMIFS(Gastos!$J$7:$J$180,Gastos!$A$7:$A$180,$A7,Gastos!$B$7:$B$180,G$6)) -> 0 | H7: =IF($A7="","",$B7-SUM($D7:$G7)) -> 0 | I7: =IF($A7="","",COUNTIFS(Gastos!$A$7:$A$180,$A7)) -> 0
A8: =IF($A7="","",IF($A7+1>Painel!$C$8,"",$A7+1)) -> 46508 | B8: =IF($A8="","",SUMIFS(Gastos!$J$7:$J$180,Gastos!$A$7:$A$180,$A8)) -> 0 | C8: =IF($A8="","",SUM($B$7:$B8)) -> 0 | D8: =IF($A8="","",SUMIFS(Gastos!$J$7:$J$180,Gastos!$A$7:$A$180,$A8,Gastos!$B$7:$B$180,D$6)) -> 0 | E8: =IF($A8="","",SUMIFS(Gastos!$J$7:$J$180,Gastos!$A$7:$A$180,$A8,Gastos!$B$7:$B$180,E$6)) -> 0 | F8: =IF($A8="","",SUMIFS(Gastos!$J$7:$J$180,Gastos!$A$7:$A$180,$A8,Gastos!$B$7:$B$180,F$6)) -> 0 | G8: =IF($A8="","",SUMIFS(Gastos!$J$7:$J$180,Gastos!$A$7:$A$180,$A8,Gastos!$B$7:$B$180,G$6)) -> 0 | H8: =IF($A8="","",$B8-SUM($D8:$G8)) -> 0 | I8: =IF($A8="","",COUNTIFS(Gastos!$A$7:$A$180,$A8)) -> 0
A9: =IF($A8="","",IF($A8+1>Painel!$C$8,"",$A8+1)) -> 46509 | B9: =IF($A9="","",SUMIFS(Gastos!$J$7:$J$180,Gastos!$A$7:$A$180,$A9)) -> 0 | C9: =IF($A9="","",SUM($B$7:$B9)) -> 0 | D9: =IF($A9="","",SUMIFS(Gastos!$J$7:$J$180,Gastos!$A$7:$A$180,$A9,Gastos!$B$7:$B$180,D$6)) -> 0 | E9: =IF($A9="","",SUMIFS(Gastos!$J$7:$J$180,Gastos!$A$7:$A$180,$A9,Gastos!$B$7:$B$180,E$6)) -> 0 | F9: =IF($A9="","",SUMIFS(Gastos!$J$7:$J$180,Gastos!$A$7:$A$180,$A9,Gastos!$B$7:$B$180,F$6)) -> 0 | G9: =IF($A9="","",SUMIFS(Gastos!$J$7:$J$180,Gastos!$A$7:$A$180,$A9,Gastos!$B$7:$B$180,G$6)) -> 0 | H9: =IF($A9="","",$B9-SUM($D9:$G9)) -> 0 | I9: =IF($A9="","",COUNTIFS(Gastos!$A$7:$A$180,$A9)) -> 0
A10: =IF($A9="","",IF($A9+1>Painel!$C$8,"",$A9+1)) -> 46510 | B10: =IF($A10="","",SUMIFS(Gastos!$J$7:$J$180,Gastos!$A$7:$A$180,$A10)) -> 0 | C10: =IF($A10="","",SUM($B$7:$B10)) -> 0 | D10: =IF($A10="","",SUMIFS(Gastos!$J$7:$J$180,Gastos!$A$7:$A$180,$A10,Gastos!$B$7:$B$180,D$6)) -> 0 | E10: =IF($A10="","",SUMIFS(Gastos!$J$7:$J$180,Gastos!$A$7:$A$180,$A10,Gastos!$B$7:$B$180,E$6)) -> 0 | F10: =IF($A10="","",SUMIFS(Gastos!$J$7:$J$180,Gastos!$A$7:$A$180,$A10,Gastos!$B$7:$B$180,F$6)) -> 0 | G10: =IF($A10="","",SUMIFS(Gastos!$J$7:$J$180,Gastos!$A$7:$A$180,$A10,Gastos!$B$7:$B$180,G$6)) -> 0 | H10: =IF($A10="","",$B10-SUM($D10:$G10)) -> 0 | I10: =IF($A10="","",COUNTIFS(Gastos!$A$7:$A$180,$A10)) -> 0
A11: =IF($A10="","",IF($A10+1>Painel!$C$8,"",$A10+1)) -> 46511 | B11: =IF($A11="","",SUMIFS(Gastos!$J$7:$J$180,Gastos!$A$7:$A$180,$A11)) -> 0 | C11: =IF($A11="","",SUM($B$7:$B11)) -> 0 | D11: =IF($A11="","",SUMIFS(Gastos!$J$7:$J$180,Gastos!$A$7:$A$180,$A11,Gastos!$B$7:$B$180,D$6)) -> 0 | E11: =IF($A11="","",SUMIFS(Gastos!$J$7:$J$180,Gastos!$A$7:$A$180,$A11,Gastos!$B$7:$B$180,E$6)) -> 0 | F11: =IF($A11="","",SUMIFS(Gastos!$J$7:$J$180,Gastos!$A$7:$A$180,$A11,Gastos!$B$7:$B$180,F$6)) -> 0 | G11: =IF($A11="","",SUMIFS(Gastos!$J$7:$J$180,Gastos!$A$7:$A$180,$A11,Gastos!$B$7:$B$180,G$6)) -> 0 | H11: =IF($A11="","",$B11-SUM($D11:$G11)) -> 0 | I11: =IF($A11="","",COUNTIFS(Gastos!$A$7:$A$180,$A11)) -> 0
A12: =IF($A11="","",IF($A11+1>Painel!$C$8,"",$A11+1)) -> 46512 | B12: =IF($A12="","",SUMIFS(Gastos!$J$7:$J$180,Gastos!$A$7:$A$180,$A12)) -> 0 | C12: =IF($A12="","",SUM($B$7:$B12)) -> 0 | D12: =IF($A12="","",SUMIFS(Gastos!$J$7:$J$180,Gastos!$A$7:$A$180,$A12,Gastos!$B$7:$B$180,D$6)) -> 0 | E12: =IF($A12="","",SUMIFS(Gastos!$J$7:$J$180,Gastos!$A$7:$A$180,$A12,Gastos!$B$7:$B$180,E$6)) -> 0 | F12: =IF($A12="","",SUMIFS(Gastos!$J$7:$J$180,Gastos!$A$7:$A$180,$A12,Gastos!$B$7:$B$180,F$6)) -> 0 | G12: =IF($A12="","",SUMIFS(Gastos!$J$7:$J$180,Gastos!$A$7:$A$180,$A12,Gastos!$B$7:$B$180,G$6)) -> 0 | H12: =IF($A12="","",$B12-SUM($D12:$G12)) -> 0 | I12: =IF($A12="","",COUNTIFS(Gastos!$A$7:$A$180,$A12)) -> 0
A13: =IF($A12="","",IF($A12+1>Painel!$C$8,"",$A12+1)) -> 46513 | B13: =IF($A13="","",SUMIFS(Gastos!$J$7:$J$180,Gastos!$A$7:$A$180,$A13)) -> 0 | C13: =IF($A13="","",SUM($B$7:$B13)) -> 0 | D13: =IF($A13="","",SUMIFS(Gastos!$J$7:$J$180,Gastos!$A$7:$A$180,$A13,Gastos!$B$7:$B$180,D$6)) -> 0 | E13: =IF($A13="","",SUMIFS(Gastos!$J$7:$J$180,Gastos!$A$7:$A$180,$A13,Gastos!$B$7:$B$180,E$6)) -> 0 | F13: =IF($A13="","",SUMIFS(Gastos!$J$7:$J$180,Gastos!$A$7:$A$180,$A13,Gastos!$B$7:$B$180,F$6)) -> 0 | G13: =IF($A13="","",SUMIFS(Gastos!$J$7:$J$180,Gastos!$A$7:$A$180,$A13,Gastos!$B$7:$B$180,G$6)) -> 0 | H13: =IF($A13="","",$B13-SUM($D13:$G13)) -> 0 | I13: =IF($A13="","",COUNTIFS(Gastos!$A$7:$A$180,$A13)) -> 0
A14: =IF($A13="","",IF($A13+1>Painel!$C$8,"",$A13+1)) -> 46514 | B14: =IF($A14="","",SUMIFS(Gastos!$J$7:$J$180,Gastos!$A$7:$A$180,$A14)) -> 0 | C14: =IF($A14="","",SUM($B$7:$B14)) -> 0 | D14: =IF($A14="","",SUMIFS(Gastos!$J$7:$J$180,Gastos!$A$7:$A$180,$A14,Gastos!$B$7:$B$180,D$6)) -> 0 | E14: =IF($A14="","",SUMIFS(Gastos!$J$7:$J$180,Gastos!$A$7:$A$180,$A14,Gastos!$B$7:$B$180,E$6)) -> 0 | F14: =IF($A14="","",SUMIFS(Gastos!$J$7:$J$180,Gastos!$A$7:$A$180,$A14,Gastos!$B$7:$B$180,F$6)) -> 0 | G14: =IF($A14="","",SUMIFS(Gastos!$J$7:$J$180,Gastos!$A$7:$A$180,$A14,Gastos!$B$7:$B$180,G$6)) -> 0 | H14: =IF($A14="","",$B14-SUM($D14:$G14)) -> 0 | I14: =IF($A14="","",COUNTIFS(Gastos!$A$7:$A$180,$A14)) -> 0
A15: =IF($A14="","",IF($A14+1>Painel!$C$8,"",$A14+1)) -> 46515 | B15: =IF($A15="","",SUMIFS(Gastos!$J$7:$J$180,Gastos!$A$7:$A$180,$A15)) -> 0 | C15: =IF($A15="","",SUM($B$7:$B15)) -> 0 | D15: =IF($A15="","",SUMIFS(Gastos!$J$7:$J$180,Gastos!$A$7:$A$180,$A15,Gastos!$B$7:$B$180,D$6)) -> 0 | E15: =IF($A15="","",SUMIFS(Gastos!$J$7:$J$180,Gastos!$A$7:$A$180,$A15,Gastos!$B$7:$B$180,E$6)) -> 0 | F15: =IF($A15="","",SUMIFS(Gastos!$J$7:$J$180,Gastos!$A$7:$A$180,$A15,Gastos!$B$7:$B$180,F$6)) -> 0 | G15: =IF($A15="","",SUMIFS(Gastos!$J$7:$J$180,Gastos!$A$7:$A$180,$A15,Gastos!$B$7:$B$180,G$6)) -> 0 | H15: =IF($A15="","",$B15-SUM($D15:$G15)) -> 0 | I15: =IF($A15="","",COUNTIFS(Gastos!$A$7:$A$180,$A15)) -> 0
A16: =IF($A15="","",IF($A15+1>Painel!$C$8,"",$A15+1)) -> 46516 | B16: =IF($A16="","",SUMIFS(Gastos!$J$7:$J$180,Gastos!$A$7:$A$180,$A16)) -> 0 | C16: =IF($A16="","",SUM($B$7:$B16)) -> 0 | D16: =IF($A16="","",SUMIFS(Gastos!$J$7:$J$180,Gastos!$A$7:$A$180,$A16,Gastos!$B$7:$B$180,D$6)) -> 0 | E16: =IF($A16="","",SUMIFS(Gastos!$J$7:$J$180,Gastos!$A$7:$A$180,$A16,Gastos!$B$7:$B$180,E$6)) -> 0 | F16: =IF($A16="","",SUMIFS(Gastos!$J$7:$J$180,Gastos!$A$7:$A$180,$A16,Gastos!$B$7:$B$180,F$6)) -> 0 | G16: =IF($A16="","",SUMIFS(Gastos!$J$7:$J$180,Gastos!$A$7:$A$180,$A16,Gastos!$B$7:$B$180,G$6)) -> 0 | H16: =IF($A16="","",$B16-SUM($D16:$G16)) -> 0 | I16: =IF($A16="","",COUNTIFS(Gastos!$A$7:$A$180,$A16)) -> 0
A17: =IF($A16="","",IF($A16+1>Painel!$C$8,"",$A16+1)) -> 46517 | B17: =IF($A17="","",SUMIFS(Gastos!$J$7:$J$180,Gastos!$A$7:$A$180,$A17)) -> 0 | C17: =IF($A17="","",SUM($B$7:$B17)) -> 0 | D17: =IF($A17="","",SUMIFS(Gastos!$J$7:$J$180,Gastos!$A$7:$A$180,$A17,Gastos!$B$7:$B$180,D$6)) -> 0 | E17: =IF($A17="","",SUMIFS(Gastos!$J$7:$J$180,Gastos!$A$7:$A$180,$A17,Gastos!$B$7:$B$180,E$6)) -> 0 | F17: =IF($A17="","",SUMIFS(Gastos!$J$7:$J$180,Gastos!$A$7:$A$180,$A17,Gastos!$B$7:$B$180,F$6)) -> 0 | G17: =IF($A17="","",SUMIFS(Gastos!$J$7:$J$180,Gastos!$A$7:$A$180,$A17,Gastos!$B$7:$B$180,G$6)) -> 0 | H17: =IF($A17="","",$B17-SUM($D17:$G17)) -> 0 | I17: =IF($A17="","",COUNTIFS(Gastos!$A$7:$A$180,$A17)) -> 0
A18: =IF($A17="","",IF($A17+1>Painel!$C$8,"",$A17+1)) -> 46518 | B18: =IF($A18="","",SUMIFS(Gastos!$J$7:$J$180,Gastos!$A$7:$A$180,$A18)) -> 0 | C18: =IF($A18="","",SUM($B$7:$B18)) -> 0 | D18: =IF($A18="","",SUMIFS(Gastos!$J$7:$J$180,Gastos!$A$7:$A$180,$A18,Gastos!$B$7:$B$180,D$6)) -> 0 | E18: =IF($A18="","",SUMIFS(Gastos!$J$7:$J$180,Gastos!$A$7:$A$180,$A18,Gastos!$B$7:$B$180,E$6)) -> 0 | F18: =IF($A18="","",SUMIFS(Gastos!$J$7:$J$180,Gastos!$A$7:$A$180,$A18,Gastos!$B$7:$B$180,F$6)) -> 0 | G18: =IF($A18="","",SUMIFS(Gastos!$J$7:$J$180,Gastos!$A$7:$A$180,$A18,Gastos!$B$7:$B$180,G$6)) -> 0 | H18: =IF($A18="","",$B18-SUM($D18:$G18)) -> 0 | I18: =IF($A18="","",COUNTIFS(Gastos!$A$7:$A$180,$A18)) -> 0
A19: =IF($A18="","",IF($A18+1>Painel!$C$8,"",$A18+1)) -> 46519 | B19: =IF($A19="","",SUMIFS(Gastos!$J$7:$J$180,Gastos!$A$7:$A$180,$A19)) -> 0 | C19: =IF($A19="","",SUM($B$7:$B19)) -> 0 | D19: =IF($A19="","",SUMIFS(Gastos!$J$7:$J$180,Gastos!$A$7:$A$180,$A19,Gastos!$B$7:$B$180,D$6)) -> 0 | E19: =IF($A19="","",SUMIFS(Gastos!$J$7:$J$180,Gastos!$A$7:$A$180,$A19,Gastos!$B$7:$B$180,E$6)) -> 0 | F19: =IF($A19="","",SUMIFS(Gastos!$J$7:$J$180,Gastos!$A$7:$A$180,$A19,Gastos!$B$7:$B$180,F$6)) -> 0 | G19: =IF($A19="","",SUMIFS(Gastos!$J$7:$J$180,Gastos!$A$7:$A$180,$A19,Gastos!$B$7:$B$180,G$6)) -> 0 | H19: =IF($A19="","",$B19-SUM($D19:$G19)) -> 0 | I19: =IF($A19="","",COUNTIFS(Gastos!$A$7:$A$180,$A19)) -> 0
... A46: =IF($A45="","",IF($A45+1>Painel!$C$8,"",$A45+1)) | B46: =IF($A46="","",SUMIFS(Gastos!$J$7:$J$180,Gastos!$A$7:$A$180,$A46)) | C46: =IF($A46="","",SUM($B$7:$B46)) | D46: =IF($A46="","",SUMIFS(Gastos!$J$7:$J$180,Gastos!$A$7:$A$180,$A46,Gastos!$B$7:$B$180,D$6)) | E46: =IF($A46="","",SUMIFS(Gastos!$J$7:$J$180,Gastos!$A$7:$A$180,$A46,Gastos!$B$7:$B$180,E$6)) | F46: =IF($A46="","",SUMIFS(Gastos!$J$7:$J$180,Gastos!$A$7:$A$180,$A46,Gastos!$B$7:$B$180,F$6)) | G46: =IF($A46="","",SUMIFS(Gastos!$J$7:$J$180,Gastos!$A$7:$A$180,$A46,Gastos!$B$7:$B$180,G$6)) | H46: =IF($A46="","",$B46-SUM($D46:$G46)) | I46: =IF($A46="","",COUNTIFS(Gastos!$A$7:$A$180,$A46))
A47: TOTAL | B47: =SUM(B7:B46) -> 0 | D47: =SUM(D7:D46) -> 0 | E47: =SUM(E7:E46) -> 0 | F47: =SUM(F7:F46) -> 0 | G47: =SUM(G7:G46) -> 0 | H47: =SUM(H7:H46) -> 0 | I47: =SUM(I7:I46) -> 0

Sheet Listas
B3: LISTAS DOS MENUS SUSPENSOS
B4: Edite, acrescente ou renomeie itens aqui — os menus e as tabelas do Painel acompanham sozinhos.
B6: CATEGORIAS | D6: FORMAS DE PAGAMENTO | F6: STATUS DO GASTO | H6: QUEM PAGOU | J6: CIDADES / LOCAIS | L6: STATUS DA RESERVA
B7: Passagens Aéreas | D7: Dinheiro (iene) | F7: Pago | H7: Viajante 1 | J7: Tóquio | L7: A fazer
B8: Hospedagem | D8: Dinheiro (real) | F8: Pendente | H8: Viajante 2 | J8: Quioto | L8: Pesquisando
B9: Transporte no Japão (trens/shinkansen) | D9: Cartão de crédito | F9: Parcelado | H9: Dividido | J9: Osaka | L9: Reservado
B10: Transporte local (metrô/ônibus/táxi) | D10: Cartão de débito | F10: Reembolsado | J10: Nara | L10: Pago
B11: Alimentação | D11: Cartão internacional (Wise/Nomad) | J11: Kawaguchiko / Monte Fuji
B12: Passeios e Ingressos | D12: IC Card (Suica/Pasmo) | J12: Tokyo Disney Resort
B13: Tokyo Disney | D13: PIX | J13: Em trânsito
B14: Compras e Souvenirs | D14: Transferência / Boleto | J14: Brasil (pré-viagem)
B15: Seguro Viagem | J15: Outro
B16: Chip / Internet
B17: Documentos (passaporte etc.)
B18: Bagagem e Equipamentos
B19: Outros
B28: Não deixe linha em branco no meio de uma lista: o menu suspenso para na primeira lacuna.
